Workbook

Sheet README
A1: Project Portfolio Tracker — Excel Dashboard
A2: Companion to the Excel + SQL portfolio project. Built on synthetic data.
A4: Tabs in this workbook
A6: Tab | B6: What's there
A7: Dashboard | B7: Executive view: KPI cards, project health chart, budget burn, capacity.
A8: Exec_OnePager | B8: Print-ready 1-page summary you can attach to LinkedIn or email.
A9: Data_Projects | B9: Cleaned project list with computed % complete, % budget burned, health flag.
A10: Data_Tasks | B10: Task-level data with overdue flag.
A11: Data_TimeEntries_Wk | B11: Weekly hours per employee with capacity flag.
A12: Data_Budget | B12: Monthly budget vs. actual per project with variance.
A14: How to refresh
A15: 1. Replace data in the Data_* tabs (paste from SQL output).
A16: 2. All formulas, KPIs, and charts on the Dashboard recalculate automatically.
A17: 3. Update the 'As of' date in cell B3 of the Dashboard tab.

Sheet Data_Projects
A1: project_id | B1: project_name | C1: client_name | D1: project_manager | E1: start_date | F1: planned_end_date | G1: actual_end_date | H1: status | I1: budget_amount | J1: actual_amount | K1: pct_complete | L1: pct_budget_burned | M1: health_flag | N1: overrun
A2: 1 | B2: ERP Implementation | C2: Acme Co. | D2: Ian Parker | E2: 45903 | F2: 46131 | H2: On Hold | I2: 60000 | J2: 70571.26 | K2: =IFERROR(COUNTIFS(Data_Tasks!B:B,A2,Data_Tasks!G:G,"Done")/COUNTIFS(Data_Tasks!B:B,A2),0) -> 0.125 | L2: =IFERROR(J2/I2,0) -> 1.1761877 | M2: =IF(J2>I2,"Over Budget",IF((L2-K2)>0.15,"At Risk","On Track")) -> Over Budget | N2: =J2-I2 -> 10571.26
A3: 2 | B3: CRM Migration | C3: Initech | D3: Fatima Brown | E3: 46034 | F3: 46169 | H3: On Hold | I3: 80000 | J3: 61637.85 | K3: =IFERROR(COUNTIFS(Data_Tasks!B:B,A3,Data_Tasks!G:G,"Done")/COUNTIFS(Data_Tasks!B:B,A3),0) -> 0.80952381 | L3: =IFERROR(J3/I3,0) -> 0.77047312 | M3: =IF(J3>I3,"Over Budget",IF((L3-K3)>0.15,"At Risk","On Track")) -> On Track | N3: =J3-I3 -> -18362.15
A4: 3 | B4: Cloud Cost Optimization | C4: Globex Logistics | D4: Carlos Garcia | E4: 45986 | F4: 46154 | G4: 46181 | H4: Completed | I4: 300000 | J4: 264230.08 | K4: =IFERROR(COUNTIFS(Data_Tasks!B:B,A4,Data_Tasks!G:G,"Done")/COUNTIFS(Data_Tasks!B:B,A4),0) -> 0.33333333 | L4: =IFERROR(J4/I4,0) -> 0.88076693 | M4: =IF(J4>I4,"Over Budget",IF((L4-K4)>0.15,"At Risk","On Track")) -> At Risk | N4: =J4-I4 -> -35769.92
A5: 4 | B5: Cybersecurity Uplift | C5: Acme Co. | D5: Brystal Patel | E5: 45942 | F5: 46180 | H5: In Progress | I5: 400000 | J5: 448485.6 | K5: =IFERROR(COUNTIFS(Data_Tasks!B:B,A5,Data_Tasks!G:G,"Done")/COUNTIFS(Data_Tasks!B:B,A5),0) -> 0.037037037 | L5: =IFERROR(J5/I5,0) -> 1.121214 | M5: =IF(J5>I5,"Over Budget",IF((L5-K5)>0.15,"At Risk","On Track")) -> Over Budget | N5: =J5-I5 -> 48485.6
A6: 5 | B6: Data Warehouse Rebuild | C6: Northwind Health | D6: Tara Cooper | E6: 45803 | F6: 45948 | H6: In Progress | I6: 60000 | J6: 24832.96 | K6: =IFERROR(COUNTIFS(Data_Tasks!B:B,A6,Data_Tasks!G:G,"Done")/COUNTIFS(Data_Tasks!B:B,A6),0) -> 0.3 | L6: =IFERROR(J6/I6,0) -> 0.41388267 | M6: =IF(J6>I6,"Over Budget",IF((L6-K6)>0.15,"At Risk","On Track")) -> On Track | N6: =J6-I6 -> -35167.04
A7: 6 | B7: Customer Portal Refresh | C7: Initech | D7: Ian Parker | E7: 45963 | F7: 46125 | H7: On Hold | I7: 400000 | J7: 291217.72 | K7: =IFERROR(COUNTIFS(Data_Tasks!B:B,A7,Data_Tasks!G:G,"Done")/COUNTIFS(Data_Tasks!B:B,A7),0) -> 0.8 | L7: =IFERROR(J7/I7,0) -> 0.7280443 | M7: =IF(J7>I7,"Over Budget",IF((L7-K7)>0.15,"At Risk","On Track")) -> On Track | N7: =J7-I7 -> -108782.28
A8: 7 | B8: Mobile App Launch | C8: Acme Co. | D8: (unassigned) | E8: 45879 | F8: 46230 | H8: In Progress | I8: 300000 | J8: 145584.09 | K8: =IFERROR(COUNTIFS(Data_Tasks!B:B,A8,Data_Tasks!G:G,"Done")/COUNTIFS(Data_Tasks!B:B,A8),0) -> 0.5 | L8: =IFERROR(J8/I8,0) -> 0.4852803 | M8: =IF(J8>I8,"Over Budget",IF((L8-K8)>0.15,"At Risk","On Track")) -> On Track | N8: =J8-I8 -> -154415.91
A9: 8 | B9: HR Systems Consolidation | C9: Cyberdyne | D9: Eli Nguyen | E9: 45885 | F9: 46072 | H9: On Hold | I9: 300000 | J9: 135360.05 | K9: =IFERROR(COUNTIFS(Data_Tasks!B:B,A9,Data_Tasks!G:G,"Done")/COUNTIFS(Data_Tasks!B:B,A9),0) -> 0.43333333 | L9: =IFERROR(J9/I9,0) -> 0.45120017 | M9: =IF(J9>I9,"Over Budget",IF((L9-K9)>0.15,"At Risk","On Track")) -> On Track | N9: =J9-I9 -> -164639.95
A10: 9 | B10: Compliance Remediation | C10: Initech | D10: Ian Parker | E10: 45800 | F10: 46089 | H10: Cancelled | I10: 120000 | J10: 134103.24 | K10: =IFERROR(COUNTIFS(Data_Tasks!B:B,A10,Data_Tasks!G:G,"Done")/COUNTIFS(Data_Tasks!B:B,A10),0) -> 0.055555556 | L10: =IFERROR(J10/I10,0) -> 1.117527 | M10: =IF(J10>I10,"Over Budget",IF((L10-K10)>0.15,"At Risk","On Track")) -> Over Budget | N10: =J10-I10 -> 14103.24
A11: 10 | B11: Procurement Automation | C11: Cyberdyne | D11: Tara Cooper | E11: 45933 | F11: 46108 | H11: In Progress | I11: 60000 | J11: 41299.68 | K11: =IFERROR(COUNTIFS(Data_Tasks!B:B,A11,Data_Tasks!G:G,"Done")/COUNTIFS(Data_Tasks!B:B,A11),0) -> 0.62962963 | L11: =IFERROR(J11/I11,0) -> 0.688328 | M11: =IF(J11>I11,"Over Budget",IF((L11-K11)>0.15,"At Risk","On Track")) -> On Track | N11: =J11-I11 -> -18700.32
A12: 11 | B12: Reporting Modernization | C12: Acme Co. | D12: Ian Parker | E12: 45924 | F12: 46058 | H12: In Progress | I12: 120000 | J12: 104491.44 | K12: =IFERROR(COUNTIFS(Data_Tasks!B:B,A12,Data_Tasks!G:G,"Done")/COUNTIFS(Data_Tasks!B:B,A12),0) -> 0.26666667 | L12: =IFERROR(J12/I12,0) -> 0.870762 | M12: =IF(J12>I12,"Over Budget",IF((L12-K12)>0.15,"At Risk","On Track")) -> At Risk | N12: =J12-I12 -> -15508.56
A13: 12 | B13: Network Upgrade | C13: Vandelay Imports | D13: Brystal Patel | E13: 45824 | F13: 45964 | H13: In Progress | I13: 80000 | J13: 37667.9 | K13: =IFERROR(COUNTIFS(Data_Tasks!B:B,A13,Data_Tasks!G:G,"Done")/COUNTIFS(Data_Tasks!B:B,A13),0) -> 0.37037037 | L13: =IFERROR(J13/I13,0) -> 0.47084875 | M13: =IF(J13>I13,"Over Budget",IF((L13-K13)>0.15,"At Risk","On Track")) -> On Track | N13: =J13-I13 -> -42332.1
A14: 13 | B14: Onboarding Redesign | C14: Pied Piper | D14: Dana Lee | E14: 45964 | F14: 46187 | H14: In Progress | I14: 60000 | J14: 26040.2 | K14: =IFERROR(COUNTIFS(Data_Tasks!B:B,A14,Data_Tasks!G:G,"Done")/COUNTIFS(Data_Tasks!B:B,A14),0) -> 0.37037037 | L14: =IFERROR(J14/I14,0) -> 0.43400333 | M14: =IF(J14>I14,"Over Budget",IF((L14-K14)>0.15,"At Risk","On Track")) -> On Track | N14: =J14-I14 -> -33959.8
A15: 14 | B15: Inventory Visibility | C15: Wonka Mfg | D15: Tara Cooper | E15: 46043 | F15: 46270 | H15: Cancelled | I15: 250000 | J15: 167929.01 | K15: =IFERROR(COUNTIFS(Data_Tasks!B:B,A15,Data_Tasks!G:G,"Done")/COUNTIFS(Data_Tasks!B:B,A15),0) -> 0.6 | L15: =IFERROR(J15/I15,0) -> 0.67171604 | M15: =IF(J15>I15,"Over Budget",IF((L15-K15)>0.15,"At Risk","On Track")) -> On Track | N15: =J15-I15 -> -82070.99
A16: 15 | B16: Patient Scheduling Pilot | C16: Umbrella Bio | D16: Fatima Brown | E16: 45951 | F16: 46123 | H16: Cancelled | I16: 150000 | J16: 172363.52 | K16: =IFERROR(COUNTIFS(Data_Tasks!B:B,A16,Data_Tasks!G:G,"Done")/COUNTIFS(Data_Tasks!B:B,A16),0) -> 0.13043478 | L16: =IFERROR(J16/I16,0) -> 1.1490901 | M16: =IF(J16>I16,"Over Budget",IF((L16-K16)>0.15,"At Risk","On Track")) -> Over Budget | N16: =J16-I16 -> 22363.52
... A20: 19 | B20: Service Desk Re-platform | C20: Globex Logistics | D20: Fatima Brown | E20: 46049 | F20: 46394 | H20: In Progress | I20: 200000 | J20: 95493.56 | K20: =IFERROR(COUNTIFS(Data_Tasks!B:B,A20,Data_Tasks!G:G,"Done")/COUNTIFS(Data_Tasks!B:B,A20),0) -> 0.46666667 | L20: =IFERROR(J20/I20,0) -> 0.4774678 | M20: =IF(J20>I20,"Over Budget",IF((L20-K20)>0.15,"At Risk","On Track")) -> On Track | N20: =J20-I20 -> -104506.44
A21: 20 | B21: Quality Management Rollout | C21: Vandelay Imports | D21: Tara Cooper | E21: 45860 | F21: 46193 | G21: 46201 | H21: Completed | I21: 60000 | J21: 51048.6 | K21: =IFERROR(COUNTIFS(Data_Tasks!B:B,A21,Data_Tasks!G:G,"Done")/COUNTIFS(Data_Tasks!B:B,A21),0) -> 0.17647059 | L21: =IFERROR(J21/I21,0) -> 0.85081 | M21: =IF(J21>I21,"Over Budget",IF((L21-K21)>0.15,"At Risk","On Track")) -> At Risk | N21: =J21-I21 -> -8951.4

Sheet Data_Tasks
A1: task_id | B1: project_id | C1: task_name | D1: assignee | E1: due_date | F1: completed_date | G1: status | H1: estimated_hours | I1: overdue_flag
A2: 1 | B2: 1 | C2: Hand-off integration | D2: Quinn Lewis | E2: 46079 | G2: Open | H2: 4 | I2: =IF(AND(G2<>"Done",E2<TODAY()),"Overdue","") -> Overdue
A3: 2 | B3: 1 | C3: Implement UAT plan | D3: Sofia Young | E3: 45937 | G3: In Progress | H3: 40 | I3: =IF(AND(G3<>"Done",E3<TODAY()),"Overdue","") -> Overdue
A4: 3 | B4: 1 | C4: Test stakeholder briefing | D4: Owen Murphy | E4: 45963 | G4: In Progress | H4: 80 | I4: =IF(AND(G4<>"Done",E4<TODAY()),"Overdue","") -> Overdue
A5: 4 | B5: 1 | C5: Deploy risk register | D5: Dana Lee | E5: 45977 | G5: In Progress | H5: 4 | I5: =IF(AND(G5<>"Done",E5<TODAY()),"Overdue","") -> Overdue
A6: 5 | B6: 1 | C6: Deploy requirements | D6: Alex Johnson | E6: 46072 | G6: Open | H6: 16 | I6: =IF(AND(G6<>"Done",E6<TODAY()),"Overdue","") -> Overdue
A7: 6 | B7: 1 | C7: Deploy integration | D7: Vera Cox | E7: 46107 | G7: Open | H7: 24 | I7: =IF(AND(G7<>"Done",E7<TODAY()),"Overdue","") -> Overdue
A8: 7 | B8: 1 | C8: Validate requirements | D8: Hassan Davis | E8: 46051 | G8: In Progress | H8: 4 | I8: =IF(AND(G8<>"Done",E8<TODAY()),"Overdue","") -> Overdue
A9: 8 | B9: 1 | C9: Validate requirements | D9: Xavier Green | E9: 46086 | G9: Blocked | H9: 40 | I9: =IF(AND(G9<>"Done",E9<TODAY()),"Overdue","") -> Overdue
A10: 9 | B10: 1 | C10: Implement requirements | D10: Theo Allen | E10: 46051 | G10: Open | H10: 16 | I10: =IF(AND(G10<>"Done",E10<TODAY()),"Overdue","") -> Overdue
A11: 10 | B11: 1 | C11: Draft risk register | D11: Wendy Scott | E11: 46113 | G11: Blocked | H11: 8 | I11: =IF(AND(G11<>"Done",E11<TODAY()),"Overdue","") -> Overdue
A12: 11 | B12: 1 | C12: Review training materials | D12: Zoe Smith | E12: 46084 | G12: Open | H12: 40 | I12: =IF(AND(G12<>"Done",E12<TODAY()),"Overdue","") -> Overdue
A13: 12 | B13: 1 | C13: Kickoff integration | D13: Priya Clark | E13: 46014 | G13: Blocked | H13: 80 | I13: =IF(AND(G13<>"Done",E13<TODAY()),"Overdue","") -> Overdue
... A15: 14 | B15: 1 | C15: Document test cases | D15: Aiden Hill | E15: 45955 | G15: In Progress | H15: 80 | I15: =IF(AND(G15<>"Done",E15<TODAY()),"Overdue","") -> Overdue
A16: 15 | B16: 1 | C16: Deploy integration | D16: Sam Bell | E16: 46081 | F16: 46081 | G16: Done | H16: 4 | I16: =IF(AND(G16<>"Done",E16<TODAY()),"Overdue","")
A17: 16 | B17: 1 | C17: Test reports | D17: Diana Roberts | E17: 46007 | F17: 46015 | G17: Done | H17: 16 | I17: =IF(AND(G17<>"Done",E17<TODAY()),"Overdue","")
A18: 17 | B18: 1 | C18: Test requirements | D18: Quincy Rogers | E18: 45988 | F18: 45988 | G18: Done | H18: 8 | I18: =IF(AND(G18<>"Done",E18<TODAY()),"Overdue","")
A19: 18 | B19: 1 | C19: Pilot data model | D19: Zoe Smith | E19: 46012 | G19: Open | H19: 16 | I19: =IF(AND(G19<>"Done",E19<TODAY()),"Overdue","") -> Overdue
A20: 19 | B20: 1 | C20: Configure stakeholder briefing | D20: Ian Parker | E20: 45999 | G20: In Progress | H20: 16 | I20: =IF(AND(G20<>"Done",E20<TODAY()),"Overdue","") -> Overdue
A21: 20 | B21: 1 | C21: Deploy integration | D21: Lena Reyes | E21: 45917 | G21: Open | H21: 16 | I21: =IF(AND(G21<>"Done",E21<TODAY()),"Overdue","") -> Overdue
A22: 21 | B22: 1 | C22: Configure training materials | D22: Umar Bailey | E22: 45919 | G22: Open | H22: 80 | I22: =IF(AND(G22<>"Done",E22<TODAY()),"Overdue","") -> Overdue
A23: 22 | B23: 1 | C23: Validate data model | D23: Yara Baker | E23: 45990 | G23: Open | H23: 40 | I23: =IF(AND(G23<>"Done",E23<TODAY()),"Overdue","") -> Overdue
A24: 23 | B24: 1 | C24: Kickoff rollout plan | D24: Alex Johnson | E24: 45958 | G24: Open | H24: 40 | I24: =IF(AND(G24<>"Done",E24<TODAY()),"Overdue","") -> Overdue
A25: 24 | B25: 1 | C25: Kickoff vendor SOW | D25: Vera Cox | E25: 46116 | G25: In Progress | H25: 60 | I25: =IF(AND(G25<>"Done",E25<TODAY()),"Overdue","") -> Overdue
A26: 25 | B26: 2 | C26: Approve training materials | D26: Quincy Rogers | E26: 46134 | F26: 46137 | G26: Done | H26: 80 | I26: =IF(AND(G26<>"Done",E26<TODAY()),"Overdue","")
A27: 26 | B27: 2 | C27: Validate UAT plan | D27: Quincy Rogers | E27: 46072 | F27: 46074 | G27: Done | H27: 24 | I27: =IF(AND(G27<>"Done",E27<TODAY()),"Overdue","")
A28: 27 | B28: 2 | C28: Validate integration | D28: Maya Jackson | E28: 46124 | F28: 46126 | G28: Done | H28: 24 | I28: =IF(AND(G28<>"Done",E28<TODAY()),"Overdue","")
A29: 28 | B29: 2 | C29: Approve change request | D29: Theo Allen | E29: 46138 | F29: 46136 | G29: Done | H29: 24 | I29: =IF(AND(G29<>"Done",E29<TODAY()),"Overdue","")
A30: 29 | B30: 2 | C30: Configure test cases | D30: Lena Reyes | E30: 46041 | F30: 46040 | G30: Done | H30: 40 | I30: =IF(AND(G30<>"Done",E30<TODAY()),"Overdue","")
A31: 30 | B31: 2 | C31: Plan reports | D31: Gavin Turner | E31: 46123 | F31: 46130 | G31: Done | H31: 24 | I31: =IF(AND(G31<>"Done",E31<TODAY()),"Overdue","")
A32: 31 | B32: 2 | C32: Validate stakeholder briefing | D32: Owen Murphy | E32: 46084 | F32: 46086 | G32: Done | H32: 40 | I32: =IF(AND(G32<>"Done",E32<TODAY()),"Overdue","")
A33: 32 | B33: 2 | C33: Train reports | D33: Rachel Morgan | E33: 46126 | G33: Open | H33: 16 | I33: =IF(AND(G33<>"Done",E33<TODAY()),"Overdue","") -> Overdue
A34: 33 | B34: 2 | C34: Draft requirements | D34: Priya Clark | E34: 46098 | F34: 46095 | G34: Done | H34: 24 | I34: =IF(AND(G34<>"Done",E34<TODAY()),"Overdue","")
A35: 34 | B35: 2 | C35: Kickoff vendor SOW | D35: Yara Baker | E35: 46059 | F35: 46058 | G35: Done | H35: 24 | I35: =IF(AND(G35<>"Done",E35<TODAY()),"Overdue","")
A36: 35 | B36: 2 | C36: Plan vendor SOW | D36: Alex Johnson | E36: 46143 | G36: In Progress | H36: 80 | I36: =IF(AND(G36<>"Done",E36<TODAY()),"Overdue","") -> Overdue
A37: 36 | B37: 2 | C37: Implement test cases | D37: Sam Bell | E37: 46068 | F37: 46068 | G37: Done | H37: 40 | I37: =IF(AND(G37<>"Done",E37<TODAY()),"Overdue","")
A38: 37 | B38: 2 | C38: Test risk register | D38: Hassan Davis | E38: 46159 | G38: Open | H38: 24 | I38: =IF(AND(G38<>"Done",E38<TODAY()),"Overdue","")
A39: 38 | B39: 2 | C39: Validate change request | D39: Uma King | E39: 46075 | F39: 46084 | G39: Done | H39: 80 | I39: =IF(AND(G39<>"Done",E39<TODAY()),"Overdue","")
A40: 39 | B40: 2 | C40: Configure RACI | D40: Jade Edwards | E40: 46154 | F40: 46163 | G40: Done | H40: 24 | I40: =IF(AND(G40<>"Done",E40<TODAY()),"Overdue","")
A41: 40 | B41: 2 | C41: Migrate UAT plan | D41: Will Howard | E41: 46081 | F41: 46089 | G41: Done | H41: 8 | I41: =IF(AND(G41<>"Done",E41<TODAY()),"Overdue","")
...

Sheet Data_TimeEntries_Wk
A1: employee_id | B1: employee | C1: department | D1: week_start | E1: hours_this_week | F1: capacity_flag
A2: 1 | B2: Alex Johnson | C2: Delivery | D2: 46090 | E2: 38.33 | F2: =IF(E2>45,"Overallocated",IF(E2<30,"Underutilized","OK")) -> OK
A3: 2 | B3: Brystal Patel | C3: Operations | D3: 46090 | E3: 63.74 | F3: =IF(E3>45,"Overallocated",IF(E3<30,"Underutilized","OK")) -> Overallocated
A4: 3 | B4: Carlos Garcia | C4: Finance | D4: 46090 | E4: 42.74 | F4: =IF(E4>45,"Overallocated",IF(E4<30,"Underutilized","OK")) -> OK
A5: 4 | B5: Dana Lee | C5: Operations | D5: 46090 | E5: 28.47 | F5: =IF(E5>45,"Overallocated",IF(E5<30,"Underutilized","OK")) -> Underutilized
A6: 5 | B6: Eli Nguyen | C6: Finance | D6: 46090 | E6: 35.98 | F6: =IF(E6>45,"Overallocated",IF(E6<30,"Underutilized","OK")) -> OK
A7: 6 | B7: Fatima Brown | C7: Operations | D7: 46090 | E7: 31.42 | F7: =IF(E7>45,"Overallocated",IF(E7<30,"Underutilized","OK")) -> OK
A8: 7 | B8: Grace Khan | C8: Operations | D8: 46090 | E8: 41.95 | F8: =IF(E8>45,"Overallocated",IF(E8<30,"Underutilized","OK")) -> OK
A9: 9 | B9: Imani Martin | C9: Delivery | D9: 46090 | E9: 35.76 | F9: =IF(E9>45,"Overallocated",IF(E9<30,"Underutilized","OK")) -> OK
A10: 11 | B10: Kelly Anderson | C10: Finance | D10: 46090 | E10: 41.29 | F10: =IF(E10>45,"Overallocated",IF(E10<30,"Underutilized","OK")) -> OK
A11: 12 | B11: Liam Thomas | C11: Finance | D11: 46090 | E11: 33.24 | F11: =IF(E11>45,"Overallocated",IF(E11<30,"Underutilized","OK")) -> OK
A12: 13 | B12: Maya Jackson | C12: PMO | D12: 46090 | E12: 37.67 | F12: =IF(E12>45,"Overallocated",IF(E12<30,"Underutilized","OK")) -> OK
A13: 14 | B13: Noah White | C13: Delivery | D13: 46090 | E13: 37.04 | F13: =IF(E13>45,"Overallocated",IF(E13<30,"Underutilized","OK")) -> OK
... A348: 50 | B348: Zoe Smith | C348: Delivery | D348: 46139 | E348: 27.81 | F348: =IF(E348>45,"Overallocated",IF(E348<30,"Underutilized","OK")) -> Underutilized

Sheet Data_Budget
A1: record_id | B1: project_id | C1: project_name | D1: month_start | E1: budgeted_amount | F1: actual_amount | G1: variance
A2: 1 | B2: 1 | C2: ERP Implementation | D2: 45809 | E2: 4946.34 | F2: 8607.51 | G2: =F2-E2 -> 3661.17
A3: 2 | B3: 1 | C3: ERP Implementation | D3: 45839 | E3: 4808.32 | F3: 7081.54 | G3: =F3-E3 -> 2273.22
A4: 3 | B4: 1 | C4: ERP Implementation | D4: 45870 | E4: 4850.62 | F4: 4395.82 | G4: =F4-E4 -> -454.8
A5: 4 | B5: 1 | C5: ERP Implementation | D5: 45901 | E5: 5382.81 | F5: 8182.51 | G5: =F5-E5 -> 2799.7
A6: 5 | B6: 1 | C6: ERP Implementation | D6: 45931 | E6: 4999.37 | F6: 3941.84 | G6: =F6-E6 -> -1057.53
A7: 6 | B7: 1 | C7: ERP Implementation | D7: 45962 | E7: 5378.7 | F7: 4630.66 | G7: =F7-E7 -> -748.04
A8: 7 | B8: 1 | C8: ERP Implementation | D8: 45992 | E8: 4824.8 | F8: 4583.3 | G8: =F8-E8 -> -241.5
A9: 8 | B9: 1 | C9: ERP Implementation | D9: 46023 | E9: 4888.47 | F9: 6192.54 | G9: =F9-E9 -> 1304.07
A10: 9 | B10: 1 | C10: ERP Implementation | D10: 46054 | E10: 4944.07 | F10: 5426.9 | G10: =F10-E10 -> 482.83
A11: 10 | B11: 1 | C11: ERP Implementation | D11: 46082 | E11: 5322.23 | F11: 6069.2 | G11: =F11-E11 -> 746.97
A12: 11 | B12: 1 | C12: ERP Implementation | D12: 46113 | E12: 4810.57 | F12: 4183.61 | G12: =F12-E12 -> -626.96
A13: 12 | B13: 1 | C13: ERP Implementation | D13: 46143 | E13: 5263.67 | F13: 7275.83 | G13: =F13-E13 -> 2012.16
... A241: 240 | B241: 20 | C241: Quality Management Rollout | D241: 46143 | E241: 5227.03 | F241: 2978.13 | G241: =F241-E241 -> -2248.9

Sheet Dashboard
B2: Project Portfolio — Health Dashboard
B3: As of: | C3: 46144
B4: Synthetic data | Built with Excel + SQL
B6: TOTAL PROJECTS | D6: ON TRACK | F6: AT RISK | H6: OVER BUDGET | J6: OVERDUE TASKS
B7: =COUNTA(tProjects[project_id]) -> 20 | D7: =COUNTIFS(tProjects[health_flag],"On Track") -> 11 | F7: =COUNTIFS(tProjects[health_flag],"At Risk") -> 5 | H7: =COUNTIFS(tProjects[health_flag],"Over Budget") -> 4 | J7: =COUNTIFS(tTasks[overdue_flag],"Overdue") -> 245
B11: Project Health Summary
B12: Health | C12: # Projects | D12: % of Portfolio
B13: On Track | C13: =COUNTIFS(tProjects[health_flag],B13) -> 11 | D13: =IFERROR(C13/COUNTA(tProjects[project_id]),0) -> 0.55
B14: At Risk | C14: =COUNTIFS(tProjects[health_flag],B14) -> 5 | D14: =IFERROR(C14/COUNTA(tProjects[project_id]),0) -> 0.25
B15: Over Budget | C15: =COUNTIFS(tProjects[health_flag],B15) -> 4 | D15: =IFERROR(C15/COUNTA(tProjects[project_id]),0) -> 0.2
B19: Top 5 Over-Budget Projects
B20: Project | C20: Client | D20: Budget | E20: Actual | F20: Overrun | I20: Month | J20: Planned | K20: Actual
B21: =IFERROR(IF(LARGE(tProjects[overrun],1)<=0,"",INDEX(tProjects[project_name],MATCH(LARGE(tProjects[overrun],1),tProjects[overrun],0))),"") -> Cybersecurity Uplift | C21: =IFERROR(IF(LARGE(tProjects[overrun],1)<=0,"",INDEX(tProjects[client_name],MATCH(LARGE(tProjects[overrun],1),tProjects[overrun],0))),"") -> Acme Co. | D21: =IFERROR(IF(LARGE(tProjects[overrun],1)<=0,"",INDEX(tProjects[budget_amount],MATCH(LARGE(tProjects[overrun],1),tProjects[overrun],0))),"") -> 400000 | E21: =IFERROR(IF(LARGE(tProjects[overrun],1)<=0,"",INDEX(tProjects[actual_amount],MATCH(LARGE(tProjects[overrun],1),tProjects[overrun],0))),"") -> 448485.6 | F21: =IFERROR(IF(LARGE(tProjects[overrun],1)<=0,"",LARGE(tProjects[overrun],1)),"") -> 48485.6 | I21: 45809 | J21: =SUMIFS(tBudget[budgeted_amount],tBudget[month_start],I21) -> 316596.9 | K21: =SUMIFS(tBudget[actual_amount],tBudget[month_start],I21) -> 232791.02
B22: =IFERROR(IF(LARGE(tProjects[overrun],2)<=0,"",INDEX(tProjects[project_name],MATCH(LARGE(tProjects[overrun],2),tProjects[overrun],0))),"") -> Patient Scheduling Pilot | C22: =IFERROR(IF(LARGE(tProjects[overrun],2)<=0,"",INDEX(tProjects[client_name],MATCH(LARGE(tProjects[overrun],2),tProjects[overrun],0))),"") -> Umbrella Bio | D22: =IFERROR(IF(LARGE(tProjects[overrun],2)<=0,"",INDEX(tProjects[budget_amount],MATCH(LARGE(tProjects[overrun],2),tProjects[overrun],0))),"") -> 150000 | E22: =IFERROR(IF(LARGE(tProjects[overrun],2)<=0,"",INDEX(tProjects[actual_amount],MATCH(LARGE(tProjects[overrun],2),tProjects[overrun],0))),"") -> 172363.52 | F22: =IFERROR(IF(LARGE(tProjects[overrun],2)<=0,"",LARGE(tProjects[overrun],2)),"") -> 22363.52 | I22: 45839 | J22: =SUMIFS(tBudget[budgeted_amount],tBudget[month_start],I22) -> 318655.51 | K22: =SUMIFS(tBudget[actual_amount],tBudget[month_start],I22) -> 223739.36
B23: =IFERROR(IF(LARGE(tProjects[overrun],3)<=0,"",INDEX(tProjects[project_name],MATCH(LARGE(tProjects[overrun],3),tProjects[overrun],0))),"") -> Compliance Remediation | C23: =IFERROR(IF(LARGE(tProjects[overrun],3)<=0,"",INDEX(tProjects[client_name],MATCH(LARGE(tProjects[overrun],3),tProjects[overrun],0))),"") -> Initech | D23: =IFERROR(IF(LARGE(tProjects[overrun],3)<=0,"",INDEX(tProjects[budget_amount],MATCH(LARGE(tProjects[overrun],3),tProjects[overrun],0))),"") -> 120000 | E23: =IFERROR(IF(LARGE(tProjects[overrun],3)<=0,"",INDEX(tProjects[actual_amount],MATCH(LARGE(tProjects[overrun],3),tProjects[overrun],0))),"") -> 134103.24 | F23: =IFERROR(IF(LARGE(tProjects[overrun],3)<=0,"",LARGE(tProjects[overrun],3)),"") -> 14103.24 | I23: 45870 | J23: =SUMIFS(tBudget[budgeted_amount],tBudget[month_start],I23) -> 317824.96 | K23: =SUMIFS(tBudget[actual_amount],tBudget[month_start],I23) -> 237730.05
B24: =IFERROR(IF(LARGE(tProjects[overrun],4)<=0,"",INDEX(tProjects[project_name],MATCH(LARGE(tProjects[overrun],4),tProjects[overrun],0))),"") -> ERP Implementation | C24: =IFERROR(IF(LARGE(tProjects[overrun],4)<=0,"",INDEX(tProjects[client_name],MATCH(LARGE(tProjects[overrun],4),tProjects[overrun],0))),"") -> Acme Co. | D24: =IFERROR(IF(LARGE(tProjects[overrun],4)<=0,"",INDEX(tProjects[budget_amount],MATCH(LARGE(tProjects[overrun],4),tProjects[overrun],0))),"") -> 60000 | E24: =IFERROR(IF(LARGE(tProjects[overrun],4)<=0,"",INDEX(tProjects[actual_amount],MATCH(LARGE(tProjects[overrun],4),tProjects[overrun],0))),"") -> 70571.26 | F24: =IFERROR(IF(LARGE(tProjects[overrun],4)<=0,"",LARGE(tProjects[overrun],4)),"") -> 10571.26 | I24: 45901 | J24: =SUMIFS(tBudget[budgeted_amount],tBudget[month_start],I24) -> 311002.97 | K24: =SUMIFS(tBudget[actual_amount],tBudget[month_start],I24) -> 246632.42
B25: =IFERROR(IF(LARGE(tProjects[overrun],5)<=0,"",INDEX(tProjects[project_name],MATCH(LARGE(tProjects[overrun],5),tProjects[overrun],0))),"") | C25: =IFERROR(IF(LARGE(tProjects[overrun],5)<=0,"",INDEX(tProjects[client_name],MATCH(LARGE(tProjects[overrun],5),tProjects[overrun],0))),"") | D25: =IFERROR(IF(LARGE(tProjects[overrun],5)<=0,"",INDEX(tProjects[budget_amount],MATCH(LARGE(tProjects[overrun],5),tProjects[overrun],0))),"") | E25: =IFERROR(IF(LARGE(tProjects[overrun],5)<=0,"",INDEX(tProjects[actual_amount],MATCH(LARGE(tProjects[overrun],5),tProjects[overrun],0))),"") | F25: =IFERROR(IF(LARGE(tProjects[overrun],5)<=0,"",LARGE(tProjects[overrun],5)),"") | I25: 45931 | J25: =SUMIFS(tBudget[budgeted_amount],tBudget[month_start],I25) -> 304867.78 | K25: =SUMIFS(tBudget[actual_amount],tBudget[month_start],I25) -> 252939.9
I26: 45962 | J26: =SUMIFS(tBudget[budgeted_amount],tBudget[month_start],I26) -> 315279.41 | K26: =SUMIFS(tBudget[actual_amount],tBudget[month_start],I26) -> 239124.15
I27: 45992 | J27: =SUMIFS(tBudget[budgeted_amount],tBudget[month_start],I27) -> 317134.37 | K27: =SUMIFS(tBudget[actual_amount],tBudget[month_start],I27) -> 238608.19
B28: Monthly Spend — Planned vs Actual | I28: 46023 | J28: =SUMIFS(tBudget[budgeted_amount],tBudget[month_start],I28) -> 310567.4 | K28: =SUMIFS(tBudget[actual_amount],tBudget[month_start],I28) -> 263791.38
I29: 46054 | J29: =SUMIFS(tBudget[budgeted_amount],tBudget[month_start],I29) -> 316348.69 | K29: =SUMIFS(tBudget[actual_amount],tBudget[month_start],I29) -> 227558.44
I30: 46082 | J30: =SUMIFS(tBudget[budgeted_amount],tBudget[month_start],I30) -> 312110.86 | K30: =SUMIFS(tBudget[actual_amount],tBudget[month_start],I30) -> 231435.61
I31: 46113 | J31: =SUMIFS(tBudget[budgeted_amount],tBudget[month_start],I31) -> 309765.78 | K31: =SUMIFS(tBudget[actual_amount],tBudget[month_start],I31) -> 259467.29
I32: 46143 | J32: =SUMIFS(tBudget[budgeted_amount],tBudget[month_start],I32) -> 313370.87 | K32: =SUMIFS(tBudget[actual_amount],tBudget[month_start],I32) -> 225552.74
B46: Capacity Hot List — Overallocated Employees (any week >45 hrs)
B47: Employee | C47: Department | D47: # Weeks Overallocated
B48: =IFERROR(IF(INT(LARGE(F61:F110,1))=0,"",INDEX(D61:D110,MATCH(LARGE(F61:F110,1),F61:F110,0))),"") -> Hailey Diaz | C48: =IFERROR(IF(INT(LARGE(F61:F110,1))=0,"",INDEX(E61:E110,MATCH(LARGE(F61:F110,1),F61:F110,0))),"") -> Operations | D48: =IFERROR(IF(INT(LARGE(F61:F110,1))=0,"",INT(LARGE(F61:F110,1))),"") -> 4
B49: =IFERROR(IF(INT(LARGE(F61:F110,2))=0,"",INDEX(D61:D110,MATCH(LARGE(F61:F110,2),F61:F110,0))),"") -> Sam Bell | C49: =IFERROR(IF(INT(LARGE(F61:F110,2))=0,"",INDEX(E61:E110,MATCH(LARGE(F61:F110,2),F61:F110,0))),"") -> Finance | D49: =IFERROR(IF(INT(LARGE(F61:F110,2))=0,"",INT(LARGE(F61:F110,2))),"") -> 3
B50: =IFERROR(IF(INT(LARGE(F61:F110,3))=0,"",INDEX(D61:D110,MATCH(LARGE(F61:F110,3),F61:F110,0))),"") -> Paige Cook | C50: =IFERROR(IF(INT(LARGE(F61:F110,3))=0,"",INDEX(E61:E110,MATCH(LARGE(F61:F110,3),F61:F110,0))),"") -> Design | D50: =IFERROR(IF(INT(LARGE(F61:F110,3))=0,"",INT(LARGE(F61:F110,3))),"") -> 3
B51: =IFERROR(IF(INT(LARGE(F61:F110,4))=0,"",INDEX(D61:D110,MATCH(LARGE(F61:F110,4),F61:F110,0))),"") -> Owen Murphy | C51: =IFERROR(IF(INT(LARGE(F61:F110,4))=0,"",INDEX(E61:E110,MATCH(LARGE(F61:F110,4),F61:F110,0))),"") -> Operations | D51: =IFERROR(IF(INT(LARGE(F61:F110,4))=0,"",INT(LARGE(F61:F110,4))),"") -> 3
B52: =IFERROR(IF(INT(LARGE(F61:F110,5))=0,"",INDEX(D61:D110,MATCH(LARGE(F61:F110,5),F61:F110,0))),"") -> Nina Morris | C52: =IFERROR(IF(INT(LARGE(F61:F110,5))=0,"",INDEX(E61:E110,MATCH(LARGE(F61:F110,5),F61:F110,0))),"") -> Engineering | D52: =IFERROR(IF(INT(LARGE(F61:F110,5))=0,"",INT(LARGE(F61:F110,5))),"") -> 3
B53: =IFERROR(IF(INT(LARGE(F61:F110,6))=0,"",INDEX(D61:D110,MATCH(LARGE(F61:F110,6),F61:F110,0))),"") -> Jade Edwards | C53: =IFERROR(IF(INT(LARGE(F61:F110,6))=0,"",INDEX(E61:E110,MATCH(LARGE(F61:F110,6),F61:F110,0))),"") -> Engineering | D53: =IFERROR(IF(INT(LARGE(F61:F110,6))=0,"",INT(LARGE(F61:F110,6))),"") -> 3
B54: =IFERROR(IF(INT(LARGE(F61:F110,7))=0,"",INDEX(D61:D110,MATCH(LARGE(F61:F110,7),F61:F110,0))),"") -> Caleb Carter | C54: =IFERROR(IF(INT(LARGE(F61:F110,7))=0,"",INDEX(E61:E110,MATCH(LARGE(F61:F110,7),F61:F110,0))),"") -> Finance | D54: =IFERROR(IF(INT(LARGE(F61:F110,7))=0,"",INT(LARGE(F61:F110,7))),"") -> 3
B55: =IFERROR(IF(INT(LARGE(F61:F110,8))=0,"",INDEX(D61:D110,MATCH(LARGE(F61:F110,8),F61:F110,0))),"") -> Aiden Hill | C55: =IFERROR(IF(INT(LARGE(F61:F110,8))=0,"",INDEX(E61:E110,MATCH(LARGE(F61:F110,8),F61:F110,0))),"") -> PMO | D55: =IFERROR(IF(INT(LARGE(F61:F110,8))=0,"",INT(LARGE(F61:F110,8))),"") -> 3
B56: =IFERROR(IF(INT(LARGE(F61:F110,9))=0,"",INDEX(D61:D110,MATCH(LARGE(F61:F110,9),F61:F110,0))),"") -> Victor Wright | C56: =IFERROR(IF(INT(LARGE(F61:F110,9))=0,"",INDEX(E61:E110,MATCH(LARGE(F61:F110,9),F61:F110,0))),"") -> Operations | D56: =IFERROR(IF(INT(LARGE(F61:F110,9))=0,"",INT(LARGE(F61:F110,9))),"") -> 3
B57: =IFERROR(IF(INT(LARGE(F61:F110,10))=0,"",INDEX(D61:D110,MATCH(LARGE(F61:F110,10),F61:F110,0))),"") -> Sofia Young | C57: =IFERROR(IF(INT(LARGE(F61:F110,10))=0,"",INDEX(E61:E110,MATCH(LARGE(F61:F110,10),F61:F110,0))),"") -> PMO | D57: =IFERROR(IF(INT(LARGE(F61:F110,10))=0,"",INT(LARGE(F61:F110,10))),"") -> 3
B60: (helper) | C60: employee_id | D60: name | E60: dept | F60: overalloc_wks
C61: 1 | D61: Alex Johnson | E61: Delivery | F61: =COUNTIFS(tTime[employee_id],C61,tTime[capacity_flag],"Overallocated")+C61/1000000 -> 1e-06
C62: 2 | D62: Brystal Patel | E62: Operations | F62: =COUNTIFS(tTime[employee_id],C62,tTime[capacity_flag],"Overallocated")+C62/1000000 -> 2.000002
C63: 3 | D63: Carlos Garcia | E63: Finance | F63: =COUNTIFS(tTime[employee_id],C63,tTime[capacity_flag],"Overallocated")+C63/1000000 -> 2.000003
...

Sheet Exec_OnePager
B2: Project Portfolio Health — Executive Summary
B3: Synthetic dataset | Sample portfolio piece
B5: PROJECTS | D5: % ON TRACK | F5: % OVER BUDGET | H5: TOTAL OVERRUN
B6: =COUNTA(tProjects[project_id]) -> 20 | D6: =IFERROR(COUNTIFS(tProjects[health_flag],"On Track")/COUNTA(tProjects[project_id]),0) -> 0.55 | F6: =IFERROR(COUNTIFS(tProjects[health_flag],"Over Budget")/COUNTA(tProjects[project_id]),0) -> 0.2 | H6: =SUMIFS(tProjects[overrun],tProjects[overrun],">0") -> 95523.62
B10: What this dashboard shows
B11: • Single weekly view of project health across all 20 projects.
B12: • Health flag is automatic: 'Over Budget' when actuals exceed plan; 'At Risk' when
B13: budget burn is running >15 percentage points ahead of % complete.
B14: • Capacity hot list flags employees logging >45 hours for any week in the last 8.
B16: Recommended actions
B17: 1. Re-baseline the over-budget projects with the COO this week.
B18: 2. Open weekly check-in on any project where (% burned − % complete) > 15.
B19: 3. Redistribute work from overallocated staff before quality slips.
B20: 4. Replace ad-hoc PM emails with this dashboard, refreshed every Monday.
B23: Built by Brystal | Excel + SQL portfolio piece
